<?xml version="1.0" ?>
<!-- =================================================================================== -->
<!-- |    This document was autogenerated by xacro from /home/roboert/MP_WS/src/cr5_description/urdf/cr5_dh.urdf.xacro | -->
<!-- |    EDITING THIS FILE BY HAND IS NOT RECOMMENDED                                 | -->
<!-- =================================================================================== -->
<robot name="cr5">
    <link name="base_link">
        <inertial>
            <origin rpy="0 0 0" xyz="-8.0961E-06 0.0019103 0.028995" />
            <mass value="0.90882" />
            <inertia ixx="0.0014545" ixy="4.2968E-08" ixz="-1.8199E-07" iyy="0.001345" iyz="-6.243E-06" izz="0.002155" />
        </inertial>
        <visual>
            <origin rpy="0 0 0" xyz="0 0 0" />
            <geometry>
                <mesh filename="package://cr5_description/meshes/base_link.STL" />
            </geometry>
            <material name="">
                <color rgba="1 1 1 1" />
            </material>
        </visual>
        <collision>
            <origin rpy="0 0 0" xyz="0 0 0" />
            <geometry>
                <mesh filename="package://cr5_description/meshes/base_link.STL" />
            </geometry>
        </collision>
    </link>
    <link name="Link1">
        <inertial>
            <origin rpy="0 0 0" xyz="-8.7268E-07 -0.0032576 -0.0076748" />
            <mass value="1.6123" />
            <inertia ixx="0.0029122" ixy="5.7387E-09" ixz="1.9945E-08" iyy="0.0028191" iyz="0.00044094" izz="0.0032836" />
        </inertial>
        <visual>
            <origin rpy="0 0 0" xyz="0 0 0" />
            <geometry>
                <mesh filename="package://cr5_description/meshes/Link1.STL" />
            </geometry>
            <material name="">
                <color rgba="1 1 1 1" />
            </material>
        </visual>
        <collision>
            <origin rpy="0 0 0" xyz="0 0 0" />
            <geometry>
                <mesh filename="package://cr5_description/meshes/Link1.STL" />
            </geometry>
        </collision>
    </link>
    <joint name="joint1" type="revolute">
        <origin rpy="0 0 0" xyz="0 0 0.147" />
        <parent link="base_link" />
        <child link="Link1" />
        <axis xyz="0 0 1" />
        <limit effort="100" lower="-3.14" upper="3.14" velocity="5" />
    </joint>
    <link name="Link2">
        <inertial>
            <origin rpy="0 0 0" xyz="-0.21351 -1.3842E-06 0.14252" />
            <mass value="5.5186" />
            <inertia ixx="0.0085919" ixy="7.5552E-07" ixz="-7.8922E-07" iyy="0.027553" iyz="1.4629E-07" izz="0.028294" />
        </inertial>
        <visual>
            <origin rpy="0 0 0" xyz="0 0 0" />
            <geometry>
                <mesh filename="package://cr5_description/meshes/Link2.STL" />
            </geometry>
            <material name="">
                <color rgba="1 1 1 1" />
            </material>
        </visual>
        <collision>
            <origin rpy="0 0 0" xyz="0 0 0" />
            <geometry>
                <mesh filename="package://cr5_description/meshes/Link2.STL" />
            </geometry>
        </collision>
    </link>
    <joint name="joint2" type="revolute">
        <origin rpy="1.5708 1.5708 0" xyz="0 0 0" />
        <parent link="Link1" />
        <child link="Link2" />
        <axis xyz="0 0 1" />
        <limit effort="100" lower="-3.14" upper="3.14" velocity="5" />
    </joint>
    <link name="Link3">
        <inertial>
            <origin rpy="0 0 0" xyz="-0.15231 -1.4079E-07 0.022693" />
            <mass value="2.8536" />
            <inertia ixx="0.0032608" ixy="-3.2147E-10" ixz="0.00012363" iyy="0.0092967" iyz="2.9478E-10" izz="0.0095552" />
        </inertial>
        <visual>
            <origin rpy="0 0 0" xyz="0 0 0" />
            <geometry>
                <mesh filename="package://cr5_description/meshes/Link3.STL" />
            </geometry>
            <material name="">
                <color rgba="1 1 1 1" />
            </material>
        </visual>
        <collision>
            <origin rpy="0 0 0" xyz="0 0 0" />
            <geometry>
                <mesh filename="package://cr5_description/meshes/Link3.STL" />
            </geometry>
        </collision>
    </link>
    <joint name="joint3" type="revolute">
        <origin rpy="0 0 0" xyz="-0.427 0 0" />
        <parent link="Link2" />
        <child link="Link3" />
        <axis xyz="0 0 1" />
        <limit effort="100" lower="-3.14" upper="3.14" velocity="5" />
    </joint>
    <link name="Link4">
        <inertial>
            <origin rpy="0 0 0" xyz="-3.2386E-07 -0.002077 -0.0015548" />
            <mass value="0.67058" />
            <inertia ixx="0.00066939" ixy="4.1975E-10" ixz="-1.0734E-08" iyy="0.00065424" iyz="0.00011081" izz="0.00065365" />
        </inertial>
        <visual>
            <origin rpy="0 0 0" xyz="0 0 0" />
            <geometry>
                <mesh filename="package://cr5_description/meshes/Link4.STL" />
            </geometry>
            <material name="">
                <color rgba="1 1 1 1" />
            </material>
        </visual>
        <collision>
            <origin rpy="0 0 0" xyz="0 0 0" />
            <geometry>
                <mesh filename="package://cr5_description/meshes/Link4.STL" />
            </geometry>
        </collision>
    </link>
    <joint name="joint4" type="revolute">
        <origin rpy="0 0 -1.5708" xyz="-0.357 0 0.141" />
        <parent link="Link3" />
        <child link="Link4" />
        <axis xyz="0 0 1" />
        <limit effort="100" lower="-3.14" upper="3.14" velocity="5" />
    </joint>
    <link name="Link5">
        <inertial>
            <origin rpy="0 0 0" xyz="-3.7738E-07 -0.0045777 -0.0012971" />
            <mass value="0.7269" />
            <inertia ixx="0.00073069" ixy="-5.7806E-09" ixz="6.7132E-09" iyy="0.00071195" iyz="-0.00011926" izz="0.00071391" />
        </inertial>
        <visual>
            <origin rpy="0 0 0" xyz="0 0 0" />
            <geometry>
                <mesh filename="package://cr5_description/meshes/Link5.STL" />
            </geometry>
            <material name="">
                <color rgba="1 1 1 1" />
            </material>
        </visual>
        <collision>
            <origin rpy="0 0 0" xyz="0 0 0" />
            <geometry>
                <mesh filename="package://cr5_description/meshes/Link5.STL" />
            </geometry>
        </collision>
    </link>
    <joint name="joint5" type="revolute">
        <origin rpy="1.5708 0 0" xyz="0 -0.116 0" />
        <parent link="Link4" />
        <child link="Link5" />
        <axis xyz="0 0 1" />
        <limit effort="100" lower="-3.14" upper="3.14" velocity="5" />
    </joint>
    <link name="Link6">
        <inertial>
            <origin rpy="0 0 0" xyz="5.0777E-11 9.3774E-05 -0.019285" />
            <mass value="0.15789" />
            <inertia ixx="7.8045E-05" ixy="6.1582E-15" ixz="6.2471E-14" iyy="7.9168E-05" iyz="-1.3822E-07" izz="0.00012951" />
        </inertial>
        <visual>
            <origin rpy="0 0 0" xyz="0 0 0" />
            <geometry>
                <mesh filename="package://cr5_description/meshes/Link6.STL" />
            </geometry>
            <material name="">
                <color rgba="1 1 1 1" />
            </material>
        </visual>
        <collision>
            <origin rpy="0 0 0" xyz="0 0 0" />
            <geometry>
                <mesh filename="package://cr5_description/meshes/Link6.STL" />
            </geometry>
        </collision>
    </link>
    <joint name="joint6" type="revolute">
        <origin rpy="-1.5708 0 0" xyz="0 0.105 0" />
        <parent link="Link5" />
        <child link="Link6" />
        <axis xyz="0 0 1" />
        <limit effort="100" lower="-3.14" upper="3.14" velocity="5" />
    </joint>
    <link name="world" />
    <joint name="world_joint" type="fixed">
        <parent link="world" />
        <child link="base_link" />
        <origin rpy="0.0 0.0 0.0" xyz="0.0 0.0 0.0" />
    </joint>
    <link name="dh_base_link">
        <inertial>
            <origin rpy="0 0 0" xyz="-3.9257E-06 -0.00027208 0.037806" />
            <mass value="0.34365" />
            <inertia ixx="0.00036805" ixy="-7.2868E-08" ixz="-5.0168E-08" iyy="0.0003341" iyz="-2.6462E-06" izz="0.00022294" />
        </inertial>
        <visual>
            <origin rpy="0 0 0" xyz="0 0 0" />
            <geometry>
                <mesh filename="package://cr5_description/dh_meshes/base_link.STL" />
            </geometry>
            <material name="">
                <color rgba="0.5 0.5 0.5 0.5" />
            </material>
        </visual>
        <collision>
            <origin rpy="0 0 0" xyz="0 0 0" />
            <geometry>
                <mesh filename="package://cr5_description/dh_meshes/base_link.STL" />
            </geometry>
        </collision>
    </link>
    <joint name="dh_joint" type="fixed">
        <parent link="Link6" />
        <child link="dh_base_link" />
        <origin rpy="0.0 0.0 0.0" xyz="0.0 0.0 0.0" />
    </joint>
    <link name="finger1_link">
        <inertial>
            <origin rpy="0 0 0" xyz="0.0030491 -0.0066024 0.0064209" />
            <mass value="0.014278" />
            <inertia ixx="1.7567E-06" ixy="-5.7832E-08" ixz="2.6803E-08" iyy="2.3034E-06" iyz="2.2145E-07" izz="1.3354E-06" />
        </inertial>
        <visual>
            <origin rpy="0 0 0" xyz="0 0 0" />
            <geometry>
                <mesh filename="package://cr5_description/dh_meshes/finger1_Link.STL" />
            </geometry>
            <material name="">
                <color rgba="0.5 0.5 0.5 0.5" />
            </material>
        </visual>
        <collision>
            <origin rpy="0 0 0" xyz="0 0 0" />
            <geometry>
                <mesh filename="package://cr5_description/dh_meshes/finger1_Link.STL" />
            </geometry>
        </collision>
    </link>
    <joint name="finger1_joint" type="prismatic">
        <origin rpy="0 0 -1.5708" xyz="0.0132 0.0265 0.093" />
        <parent link="dh_base_link" />
        <child link="finger1_link" />
        <axis xyz="1 0 0" />
        <limit effort="140" lower="0" upper="0.025" velocity="1" />
    </joint>
    <link name="finger2_link">
        <inertial>
            <origin rpy="0 0 0" xyz="0.0030491 -0.0066024 0.0064209" />
            <mass value="0.014278" />
            <inertia ixx="1.7567E-06" ixy="-5.7832E-08" ixz="2.6803E-08" iyy="2.3034E-06" iyz="2.2145E-07" izz="1.3354E-06" />
        </inertial>
        <visual>
            <origin rpy="0 0 0" xyz="0 0 0" />
            <geometry>
                <mesh filename="package://cr5_description/dh_meshes/finger2_Link.STL" />
            </geometry>
            <material name="">
                <color rgba="0.5 0.5 0.5 0.5" />
            </material>
        </visual>
        <collision>
            <origin rpy="0 0 0" xyz="0 0 0" />
            <geometry>
                <mesh filename="package://cr5_description/dh_meshes/finger2_Link.STL" />
            </geometry>
        </collision>
    </link>
    <joint name="finger2_joint" type="prismatic">
        <origin rpy="0 0 1.5708" xyz="-0.0132 -0.0265 0.093" />
        <parent link="dh_base_link" />
        <child link="finger2_link" />
        <axis xyz="1 0 0" />
        <limit effort="140" lower="0" upper="0.025" velocity="1" />
        <mimic joint="finger1_joint" multiplier="1" offset="0" />
    </joint>
    <link name="kinect_link">
        <!-- <inertial>
      <xacro:Box_inertial_matrix m="${camera_m}" l="${camera_length}" w="${camera_width}" h="${camera_height}" />
    </inertial> -->
        <collision name="collision">
            <geometry>
                <box size="0.073 0.276 0.072" />
                <origin rpy="0.0 0.0 0.0" xyz="0.0 0.0 0.0" />
            </geometry>
        </collision>
        <visual name="visual">
            <geometry>
                <mesh filename="/home/roboert/MP_WS/src/cr5_description/meshes/kinect/meshes/kinect.dae" />
            </geometry>
        </visual>
        <inertial>
            <mass value="0.1" />
            <origin xyz="0 0 0" rpy="0 0 0" />
            <inertia ixx="0.03" iyy="0.03" izz="0.03" ixy="0.0" ixz="0.0" iyz="0.0" />
        </inertial>
    </link>
    <joint name="kinect2base" type="fixed">
        <parent link="base_link" />
        <child link="kinect_link" />
        <origin rpy="0 0 3.14" xyz="1.5 0 1.0" />
    </joint>
    <!-- 虚拟相机坐标系 -->
    <link name="rgb" />
    <joint name="rgb_joint" type="fixed">
        <origin rpy="0 0 0" xyz="0 0 0.1" />
        <parent link="kinect_link" />
        <child link="rgb" />
    </joint>
    <transmission name="tran1">
        <type>transmission_interface/SimpleTransmission</type>
        <joint name="joint1">
            <hardwareInterface>hardware_interface/PositionJointInterface</hardwareInterface>
        </joint>
        <actuator name="motor1">
            <hardwareInterface>hardware_interface/PositionJointInterface</hardwareInterface>
            <mechanicalReduction>1</mechanicalReduction>
        </actuator>
    </transmission>
    <transmission name="tran1">
        <type>transmission_interface/SimpleTransmission</type>
        <joint name="joint2">
            <hardwareInterface>hardware_interface/PositionJointInterface</hardwareInterface>
        </joint>
        <actuator name="motor1">
            <hardwareInterface>hardware_interface/PositionJointInterface</hardwareInterface>
            <mechanicalReduction>1</mechanicalReduction>
        </actuator>
    </transmission>
    <transmission name="tran1">
        <type>transmission_interface/SimpleTransmission</type>
        <joint name="joint3">
            <hardwareInterface>hardware_interface/PositionJointInterface</hardwareInterface>
        </joint>
        <actuator name="motor1">
            <hardwareInterface>hardware_interface/PositionJointInterface</hardwareInterface>
            <mechanicalReduction>1</mechanicalReduction>
        </actuator>
    </transmission>
    <transmission name="tran1">
        <type>transmission_interface/SimpleTransmission</type>
        <joint name="joint4">
            <hardwareInterface>hardware_interface/PositionJointInterface</hardwareInterface>
        </joint>
        <actuator name="motor1">
            <hardwareInterface>hardware_interface/PositionJointInterface</hardwareInterface>
            <mechanicalReduction>1</mechanicalReduction>
        </actuator>
    </transmission>
    <transmission name="tran1">
        <type>transmission_interface/SimpleTransmission</type>
        <joint name="joint5">
            <hardwareInterface>hardware_interface/PositionJointInterface</hardwareInterface>
        </joint>
        <actuator name="motor1">
            <hardwareInterface>hardware_interface/PositionJointInterface</hardwareInterface>
            <mechanicalReduction>1</mechanicalReduction>
        </actuator>
    </transmission>
    <transmission name="tran1">
        <type>transmission_interface/SimpleTransmission</type>
        <joint name="joint6">
            <hardwareInterface>hardware_interface/PositionJointInterface</hardwareInterface>
        </joint>
        <actuator name="motor1">
            <hardwareInterface>hardware_interface/PositionJointInterface</hardwareInterface>
            <mechanicalReduction>1</mechanicalReduction>
        </actuator>
    </transmission>
    <transmission name="tran1">
        <type>transmission_interface/SimpleTransmission</type>
        <joint name="finger1_joint">
            <hardwareInterface>hardware_interface/PositionJointInterface</hardwareInterface>
        </joint>
        <actuator name="motor1">
            <hardwareInterface>hardware_interface/PositionJointInterface</hardwareInterface>
            <mechanicalReduction>1</mechanicalReduction>
        </actuator>
    </transmission>
    <transmission name="tran1">
        <type>transmission_interface/SimpleTransmission</type>
        <joint name="finger2_joint">
            <hardwareInterface>hardware_interface/PositionJointInterface</hardwareInterface>
        </joint>
        <actuator name="motor1">
            <hardwareInterface>hardware_interface/PositionJointInterface</hardwareInterface>
            <mechanicalReduction>1</mechanicalReduction>
        </actuator>
    </transmission>
    <gazebo>
        <plugin filename="libgazebo_ros_control.so" name="gazebo_ros_control">
            <robotNamespace>/</robotNamespace>
        </plugin>
    </gazebo>
    <gazebo reference="kinect_link">
        <material>Gazebo/Black</material>
    </gazebo>
    <gazebo reference="kinect_link">
        <sensor name="camera" type="depth">
            <always_on>true</always_on>
            <update_rate>20</update_rate>
            <camera>
                <horizontal_fov>1.047198</horizontal_fov>
                <image>
                    <width>640</width>
                    <height>480</height>
                    <format>R8G8B8</format>
                </image>
                <clip>
                    <near>0.05</near>
                    <far>3</far>
                </clip>
            </camera>
            <plugin filename="libgazebo_ros_openni_kinect.so" name="kinect_camera_controller">
                <cameraName>camera</cameraName>
                <alwaysOn>true</alwaysOn>
                <updateRate>30</updateRate>
                <imageTopicName>rgb/image_raw</imageTopicName>
                <depthImageTopicName>depth/image_raw</depthImageTopicName>
                <pointCloudTopicName>depth/points</pointCloudTopicName>
                <cameraInfoTopicName>rgb/camera_info</cameraInfoTopicName>
                <depthImageCameraInfoTopicName>depth/camera_info</depthImageCameraInfoTopicName>
                <frameName>rgb</frameName>
                <baseline>0.1</baseline>
                <distortion_k1>0.0</distortion_k1>
                <distortion_k2>0.0</distortion_k2>
                <distortion_k3>0.0</distortion_k3>
                <distortion_t1>0.0</distortion_t1>
                <distortion_t2>0.0</distortion_t2>
                <pointCloudCutoff>0.4</pointCloudCutoff>
            </plugin>
        </sensor>
    </gazebo>
</robot>

